<robot name="onshape">
<link name="link_0">
<visual>
<origin xyz="-1.3877787807898069848e-17 -0.026203896882951875635 -7.2730424135891376598e-19" rpy="2.7755575615628925837e-17 -1.2325951644158227263e-32 3.1910130767499292701e-27" />
<geometry>
<mesh filename="file:///Users/raghav/Documents/projects/robot_arm/onshape-to-robot-examples/low-cost-robot/base.stl.obj"/>
</geometry>
<material name="base_material">
<color rgba="0.61568627450980395466 0.81176470588235294379 0.92941176470588238168 1.0"/>
</material>
</visual>
<collision>
<origin xyz="-1.3877787807898069848e-17 -0.026203896882951875635 -7.2730424135891376598e-19" rpy="2.7755575615628925837e-17 -1.2325951644158227263e-32 3.1910130767499292701e-27" />
<geometry>
<mesh filename="file:///Users/raghav/Documents/projects/robot_arm/onshape-to-robot-examples/low-cost-robot/base.stl.obj"/>
</geometry>
</collision>
<visual>
<origin xyz="-6.2657287344350387492e-05 0.04160908782201944156 0.02008206293678282961" rpy="2.7755575615628925837e-17 -1.2325951644158227263e-32 3.1910130767499292701e-27" />
<geometry>
<mesh filename="file:///Users/raghav/Documents/projects/robot_arm/onshape-to-robot-examples/low-cost-robot/dc11_a01_case_cvr_dummy.stl.obj"/>
</geometry>
<material name="dc11_a01_case_cvr_dummy_material">
<color rgba="0.76862745098039220171 0.88627450980392152857 0.95294117647058818044 1.0"/>
</material>
</visual>
<collision>
<origin xyz="-6.2657287344350387492e-05 0.04160908782201944156 0.02008206293678282961" rpy="2.7755575615628925837e-17 -1.2325951644158227263e-32 3.1910130767499292701e-27" />
<geometry>
<mesh filename="file:///Users/raghav/Documents/projects/robot_arm/onshape-to-robot-examples/low-cost-robot/dc11_a01_case_cvr_dummy.stl.obj"/>
</geometry>
</collision>
<visual>
<origin xyz="-6.2657287344350387492e-05 0.04160908782201944156 0.02008206293678282961" rpy="2.7755575615628925837e-17 -1.2325951644158227263e-32 3.1910130767499292701e-27" />
<geometry>
<mesh filename="file:///Users/raghav/Documents/projects/robot_arm/onshape-to-robot-examples/low-cost-robot/dc11_a01_dummy.stl.obj"/>
</geometry>
<material name="dc11_a01_dummy_material">
<color rgba="0.64705882352941179736 0.64705882352941179736 0.64705882352941179736 1.0"/>
</material>
</visual>
<collision>
<origin xyz="-6.2657287344350387492e-05 0.04160908782201944156 0.02008206293678282961" rpy="2.7755575615628925837e-17 -1.2325951644158227263e-32 3.1910130767499292701e-27" />
<geometry>
<mesh filename="file:///Users/raghav/Documents/projects/robot_arm/onshape-to-robot-examples/low-cost-robot/dc11_a01_dummy.stl.obj"/>
</geometry>
</collision>
<inertial>
<origin xyz="-0.00021700007114736514233 0.019977290011372328404 0.014452172077149433652" rpy="0 0 0"/>
<mass value="0.06733962555274013162" />
<inertia ixx="3.9412647990890500166e-05" ixy="-1.6917449775115922648e-07"  ixz="-8.2527675233795594104e-08" iyy="3.7402608757763990989e-05" iyz="-8.3063233605931877877e-06" izz="5.7880701609149679053e-05" />
</inertial>
</link>

<link name="link_1">
<visual>
<origin xyz="0 0 0.019000000000000002998" rpy="3.141592653589793116 2.8025969286496341418e-45 2.8682827939556452799e-45" />
<geometry>
<mesh filename="file:///Users/raghav/Documents/projects/robot_arm/onshape-to-robot-examples/low-cost-robot/rotation_connector.stl.obj"/>
</geometry>
<material name="rotation_connector_material">
<color rgba="0.61568627450980395466 0.81176470588235294379 0.92941176470588238168 1.0"/>
</material>
</visual>
<collision>
<origin xyz="0 0 0.019000000000000002998" rpy="3.141592653589793116 2.8025969286496341418e-45 2.8682827939556452799e-45" />
<geometry>
<mesh filename="file:///Users/raghav/Documents/projects/robot_arm/onshape-to-robot-examples/low-cost-robot/rotation_connector.stl.obj"/>
</geometry>
</collision>
<visual>
<origin xyz="-0.00065867489763636588845 0.0015766639709812249603 -0.016150000000002148748" rpy="-3.141592653589793116 -1.5707963267948823471 0" />
<geometry>
<mesh filename="file:///Users/raghav/Documents/projects/robot_arm/onshape-to-robot-examples/low-cost-robot/dc11_a01_case_cvr_dummy.stl.obj"/>
</geometry>
<material name="dc11_a01_case_cvr_dummy_material">
<color rgba="0.76862745098039220171 0.88627450980392152857 0.95294117647058818044 1.0"/>
</material>
</visual>
<collision>
<origin xyz="-0.00065867489763636588845 0.0015766639709812249603 -0.016150000000002148748" rpy="-3.141592653589793116 -1.5707963267948823471 0" />
<geometry>
<mesh filename="file:///Users/raghav/Documents/projects/robot_arm/onshape-to-robot-examples/low-cost-robot/dc11_a01_case_cvr_dummy.stl.obj"/>
</geometry>
</collision>
<visual>
<origin xyz="-0.00065867489763636588845 0.0015766639709812249603 -0.016150000000002148748" rpy="-3.141592653589793116 -1.5707963267948823471 0" />
<geometry>
<mesh filename="file:///Users/raghav/Documents/projects/robot_arm/onshape-to-robot-examples/low-cost-robot/dc11_a01_dummy.stl.obj"/>
</geometry>
<material name="dc11_a01_dummy_material">
<color rgba="0.64705882352941179736 0.64705882352941179736 0.64705882352941179736 1.0"/>
</material>
</visual>
<collision>
<origin xyz="-0.00065867489763636588845 0.0015766639709812249603 -0.016150000000002148748" rpy="-3.141592653589793116 -1.5707963267948823471 0" />
<geometry>
<mesh filename="file:///Users/raghav/Documents/projects/robot_arm/onshape-to-robot-examples/low-cost-robot/dc11_a01_dummy.stl.obj"/>
</geometry>
</collision>
<inertial>
<origin xyz="0.00027918942835226430313 0.013518930502538224758 -0.014333557674625220513" rpy="0 0 0"/>
<mass value="0.050628351527588225101" />
<inertia ixx="1.3932921729228252918e-05" ixy="2.8557435222540705417e-07"  ixz="2.5643914428719069353e-08" iyy="9.066228100010824642e-06" iyz="2.5837193336923468571e-08" izz="1.523565784161089069e-05" />
</inertial>
</link>

<link name="link_2">
<visual>
<origin xyz="0 6.9388939039072283776e-18 0.018999999999999999528" rpy="1.570796326794896558 1.570796326794896336 0" />
<geometry>
<mesh filename="file:///Users/raghav/Documents/projects/robot_arm/onshape-to-robot-examples/low-cost-robot/connector.stl.obj"/>
</geometry>
<material name="connector_material">
<color rgba="0.49803921568627451677 0.49803921568627451677 0.49803921568627451677 1.0"/>
</material>
</visual>
<collision>
<origin xyz="0 6.9388939039072283776e-18 0.018999999999999999528" rpy="1.570796326794896558 1.570796326794896336 0" />
<geometry>
<mesh filename="file:///Users/raghav/Documents/projects/robot_arm/onshape-to-robot-examples/low-cost-robot/connector.stl.obj"/>
</geometry>
</collision>
<visual>
<origin xyz="0.10829999999999997962 0.014800000000000000655 0.010749999999999969649" rpy="-3.1415926535897917837 1.1102230246208424573e-16 3.141592653589793116" />
<geometry>
<mesh filename="file:///Users/raghav/Documents/projects/robot_arm/onshape-to-robot-examples/low-cost-robot/dc15_a01_case_m_dummy.stl.obj"/>
</geometry>
<material name="dc15_a01_case_m_dummy_material">
<color rgba="0.97254901960784312376 0.52941176470588235947 0.0039215686274509803377 1.0"/>
</material>
</visual>
<collision>
<origin xyz="0.10829999999999997962 0.014800000000000000655 0.010749999999999969649" rpy="-3.1415926535897917837 1.1102230246208424573e-16 3.141592653589793116" />
<geometry>
<mesh filename="file:///Users/raghav/Documents/projects/robot_arm/onshape-to-robot-examples/low-cost-robot/dc15_a01_case_m_dummy.stl.obj"/>
</geometry>
</collision>
<visual>
<origin xyz="0.10829999999999997962 0.014800000000000000655 0.010749999999999969649" rpy="-3.1415926535897917837 1.1102230246208424573e-16 3.141592653589793116" />
<geometry>
<mesh filename="file:///Users/raghav/Documents/projects/robot_arm/onshape-to-robot-examples/low-cost-robot/dc15_a01_case_b_dummy.stl.obj"/>
</geometry>
<material name="dc15_a01_case_b_dummy_material">
<color rgba="0.49803921568627451677 0.49803921568627451677 0.49803921568627451677 1.0"/>
</material>
</visual>
<collision>
<origin xyz="0.10829999999999997962 0.014800000000000000655 0.010749999999999969649" rpy="-3.1415926535897917837 1.1102230246208424573e-16 3.141592653589793116" />
<geometry>
<mesh filename="file:///Users/raghav/Documents/projects/robot_arm/onshape-to-robot-examples/low-cost-robot/dc15_a01_case_b_dummy.stl.obj"/>
</geometry>
</collision>
<visual>
<origin xyz="0.10829999999999997962 0.014800000000000000655 0.010749999999999969649" rpy="-3.1415926535897917837 1.1102230246208424573e-16 3.141592653589793116" />
<geometry>
<mesh filename="file:///Users/raghav/Documents/projects/robot_arm/onshape-to-robot-examples/low-cost-robot/dc15_a01_horn_idle2_dummy.stl.obj"/>
</geometry>
<material name="dc15_a01_horn_idle2_dummy_material">
<color rgba="0.98039215686274505668 0.71372549019607844922 0.0039215686274509803377 1.0"/>
</material>
</visual>
<collision>
<origin xyz="0.10829999999999997962 0.014800000000000000655 0.010749999999999969649" rpy="-3.1415926535897917837 1.1102230246208424573e-16 3.141592653589793116" />
<geometry>
<mesh filename="file:///Users/raghav/Documents/projects/robot_arm/onshape-to-robot-examples/low-cost-robot/dc15_a01_horn_idle2_dummy.stl.obj"/>
</geometry>
</collision>
<visual>
<origin xyz="0.10829999999999997962 0.014800000000000000655 0.010749999999999969649" rpy="-3.1415926535897917837 1.1102230246208424573e-16 3.141592653589793116" />
<geometry>
<mesh filename="file:///Users/raghav/Documents/projects/robot_arm/onshape-to-robot-examples/low-cost-robot/dc15_a01_horn_dummy.stl.obj"/>
</geometry>
<material name="dc15_a01_horn_dummy_material">
<color rgba="0.91764705882352937127 0.91764705882352937127 0.91764705882352937127 1.0"/>
</material>
</visual>
<collision>
<origin xyz="0.10829999999999997962 0.014800000000000000655 0.010749999999999969649" rpy="-3.1415926535897917837 1.1102230246208424573e-16 3.141592653589793116" />
<geometry>
<mesh filename="file:///Users/raghav/Documents/projects/robot_arm/onshape-to-robot-examples/low-cost-robot/dc15_a01_horn_dummy.stl.obj"/>
</geometry>
</collision>
<visual>
<origin xyz="0.10829999999999997962 0.014800000000000000655 0.010749999999999969649" rpy="-3.1415926535897917837 1.1102230246208424573e-16 3.141592653589793116" />
<geometry>
<mesh filename="file:///Users/raghav/Documents/projects/robot_arm/onshape-to-robot-examples/low-cost-robot/dc15_a01_case_f_dummy.stl.obj"/>
</geometry>
<material name="dc15_a01_case_f_dummy_material">
<color rgba="0.2313725490196078538 0.38039215686274507888 0.7058823529411765163 1.0"/>
</material>
</visual>
<collision>
<origin xyz="0.10829999999999997962 0.014800000000000000655 0.010749999999999969649" rpy="-3.1415926535897917837 1.1102230246208424573e-16 3.141592653589793116" />
<geometry>
<mesh filename="file:///Users/raghav/Documents/projects/robot_arm/onshape-to-robot-examples/low-cost-robot/dc15_a01_case_f_dummy.stl.obj"/>
</geometry>
</collision>
<inertial>
<origin xyz="0.071283098252509266568 -0.0013135243902328438102 0.018811683084683675921" rpy="0 0 0"/>
<mass value="0.05200742322197701023" />
<inertia ixx="1.1177959999252680743e-05" ixy="-4.8004079018479007247e-06"  ixz="3.5548931072628654838e-07" iyy="7.0887891266096001537e-05" iyz="8.9867531843643532168e-08" izz="6.8897838293509059489e-05" />
</inertial>
</link>

<link name="link_3">
<visual>
<origin xyz="-0.0061123580598734621183 0.010300670238652026578 0.014499999999999999001" rpy="1.8325957145940461324 1.570796326794896558 0" />
<geometry>
<mesh filename="file:///Users/raghav/Documents/projects/robot_arm/onshape-to-robot-examples/low-cost-robot/wrist_to_elbow_connector.stl.obj"/>
</geometry>
<material name="wrist_to_elbow_connector_material">
<color rgba="0.64705882352941179736 0.64705882352941179736 0.64705882352941179736 1.0"/>
</material>
</visual>
<collision>
<origin xyz="-0.0061123580598734621183 0.010300670238652026578 0.014499999999999999001" rpy="1.8325957145940461324 1.570796326794896558 0" />
<geometry>
<mesh filename="file:///Users/raghav/Documents/projects/robot_arm/onshape-to-robot-examples/low-cost-robot/wrist_to_elbow_connector.stl.obj"/>
</geometry>
</collision>
<visual>
<origin xyz="-0.088061251076824026418 0.020691030053721692905 0.022749999999996335653" rpy="-1.5768199893782454862e-13 1.4533730050366341868e-14 1.3089969389957472057" />
<geometry>
<mesh filename="file:///Users/raghav/Documents/projects/robot_arm/onshape-to-robot-examples/low-cost-robot/dc15_a01_horn_dummy.stl.obj"/>
</geometry>
<material name="dc15_a01_horn_dummy_material">
<color rgba="0.91764705882352937127 0.91764705882352937127 0.91764705882352937127 1.0"/>
</material>
</visual>
<collision>
<origin xyz="-0.088061251076824026418 0.020691030053721692905 0.022749999999996335653" rpy="-1.5768199893782454862e-13 1.4533730050366341868e-14 1.3089969389957472057" />
<geometry>
<mesh filename="file:///Users/raghav/Documents/projects/robot_arm/onshape-to-robot-examples/low-cost-robot/dc15_a01_horn_dummy.stl.obj"/>
</geometry>
</collision>
<visual>
<origin xyz="-0.088061251076824026418 0.020691030053721692905 0.022749999999996335653" rpy="-1.5768199893782454862e-13 1.4533730050366341868e-14 1.3089969389957472057" />
<geometry>
<mesh filename="file:///Users/raghav/Documents/projects/robot_arm/onshape-to-robot-examples/low-cost-robot/dc15_a01_horn_idle2_dummy.stl.obj"/>
</geometry>
<material name="dc15_a01_horn_idle2_dummy_material">
<color rgba="0.98039215686274505668 0.71372549019607844922 0.0039215686274509803377 1.0"/>
</material>
</visual>
<collision>
<origin xyz="-0.088061251076824026418 0.020691030053721692905 0.022749999999996335653" rpy="-1.5768199893782454862e-13 1.4533730050366341868e-14 1.3089969389957472057" />
<geometry>
<mesh filename="file:///Users/raghav/Documents/projects/robot_arm/onshape-to-robot-examples/low-cost-robot/dc15_a01_horn_idle2_dummy.stl.obj"/>
</geometry>
</collision>
<visual>
<origin xyz="-0.088061251076824026418 0.020691030053721692905 0.022749999999996335653" rpy="-1.5768199893782454862e-13 1.4533730050366341868e-14 1.3089969389957472057" />
<geometry>
<mesh filename="file:///Users/raghav/Documents/projects/robot_arm/onshape-to-robot-examples/low-cost-robot/dc15_a01_case_f_dummy.stl.obj"/>
</geometry>
<material name="dc15_a01_case_f_dummy_material">
<color rgba="0.2313725490196078538 0.38039215686274507888 0.7058823529411765163 1.0"/>
</material>
</visual>
<collision>
<origin xyz="-0.088061251076824026418 0.020691030053721692905 0.022749999999996335653" rpy="-1.5768199893782454862e-13 1.4533730050366341868e-14 1.3089969389957472057" />
<geometry>
<mesh filename="file:///Users/raghav/Documents/projects/robot_arm/onshape-to-robot-examples/low-cost-robot/dc15_a01_case_f_dummy.stl.obj"/>
</geometry>
</collision>
<visual>
<origin xyz="-0.088061251076824026418 0.020691030053721692905 0.022749999999996335653" rpy="-1.5768199893782454862e-13 1.4533730050366341868e-14 1.3089969389957472057" />
<geometry>
<mesh filename="file:///Users/raghav/Documents/projects/robot_arm/onshape-to-robot-examples/low-cost-robot/dc15_a01_case_m_dummy.stl.obj"/>
</geometry>
<material name="dc15_a01_case_m_dummy_material">
<color rgba="0.97254901960784312376 0.52941176470588235947 0.0039215686274509803377 1.0"/>
</material>
</visual>
<collision>
<origin xyz="-0.088061251076824026418 0.020691030053721692905 0.022749999999996335653" rpy="-1.5768199893782454862e-13 1.4533730050366341868e-14 1.3089969389957472057" />
<geometry>
<mesh filename="file:///Users/raghav/Documents/projects/robot_arm/onshape-to-robot-examples/low-cost-robot/dc15_a01_case_m_dummy.stl.obj"/>
</geometry>
</collision>
<visual>
<origin xyz="-0.088061251076824026418 0.020691030053721692905 0.022749999999996335653" rpy="-1.5768199893782454862e-13 1.4533730050366341868e-14 1.3089969389957472057" />
<geometry>
<mesh filename="file:///Users/raghav/Documents/projects/robot_arm/onshape-to-robot-examples/low-cost-robot/dc15_a01_case_b_dummy.stl.obj"/>
</geometry>
<material name="dc15_a01_case_b_dummy_material">
<color rgba="0.49803921568627451677 0.49803921568627451677 0.49803921568627451677 1.0"/>
</material>
</visual>
<collision>
<origin xyz="-0.088061251076824026418 0.020691030053721692905 0.022749999999996335653" rpy="-1.5768199893782454862e-13 1.4533730050366341868e-14 1.3089969389957472057" />
<geometry>
<mesh filename="file:///Users/raghav/Documents/projects/robot_arm/onshape-to-robot-examples/low-cost-robot/dc15_a01_case_b_dummy.stl.obj"/>
</geometry>
</collision>
<inertial>
<origin xyz="-0.049413862807944776423 0.010180605518645646085 0.01466440702977775748" rpy="0 0 0"/>
<mass value="0.058566552782009964617" />
<inertia ixx="9.6070135249593181976e-06" ixy="8.769605891085647048e-06"  ixz="3.0995042730146120295e-07" iyy="4.0150639964357244082e-05" iyz="-8.5155620319437825954e-08" izz="3.985962344572806606e-05" />
</inertial>
</link>

<link name="link_4">
<visual>
<origin xyz="-0.011005650457450499857 0.018938012661920328172 -0.0095000000000003657907" rpy="1.570796326794896558 4.3175339846533539508e-16 -1.1056784483855718362e-17" />
<geometry>
<mesh filename="file:///Users/raghav/Documents/projects/robot_arm/onshape-to-robot-examples/low-cost-robot/shoulder_rotation.stl.obj"/>
</geometry>
<material name="shoulder_rotation_material">
<color rgba="0.98039215686274505668 0.71372549019607844922 0.0039215686274509803377 1.0"/>
</material>
</visual>
<collision>
<origin xyz="-0.011005650457450499857 0.018938012661920328172 -0.0095000000000003657907" rpy="1.570796326794896558 4.3175339846533539508e-16 -1.1056784483855718362e-17" />
<geometry>
<mesh filename="file:///Users/raghav/Documents/projects/robot_arm/onshape-to-robot-examples/low-cost-robot/shoulder_rotation.stl.obj"/>
</geometry>
</collision>
<visual>
<origin xyz="-1.3290960555589065306e-05 0.022438012661919970459 0.016103323324962365293" rpy="1.570796326794896558 4.3175339846626856823e-16 -2.8792697338234302038e-14" />
<geometry>
<mesh filename="file:///Users/raghav/Documents/projects/robot_arm/onshape-to-robot-examples/low-cost-robot/dc15_a01_case_m_dummy.stl.obj"/>
</geometry>
<material name="dc15_a01_case_m_dummy_material">
<color rgba="0.97254901960784312376 0.52941176470588235947 0.0039215686274509803377 1.0"/>
</material>
</visual>
<collision>
<origin xyz="-1.3290960555589065306e-05 0.022438012661919970459 0.016103323324962365293" rpy="1.570796326794896558 4.3175339846626856823e-16 -2.8792697338234302038e-14" />
<geometry>
<mesh filename="file:///Users/raghav/Documents/projects/robot_arm/onshape-to-robot-examples/low-cost-robot/dc15_a01_case_m_dummy.stl.obj"/>
</geometry>
</collision>
<visual>
<origin xyz="-1.3290960555589065306e-05 0.022438012661919970459 0.016103323324962365293" rpy="1.570796326794896558 4.3175339846626856823e-16 -2.8792697338234302038e-14" />
<geometry>
<mesh filename="file:///Users/raghav/Documents/projects/robot_arm/onshape-to-robot-examples/low-cost-robot/dc15_a01_case_f_dummy.stl.obj"/>
</geometry>
<material name="dc15_a01_case_f_dummy_material">
<color rgba="0.2313725490196078538 0.38039215686274507888 0.7058823529411765163 1.0"/>
</material>
</visual>
<collision>
<origin xyz="-1.3290960555589065306e-05 0.022438012661919970459 0.016103323324962365293" rpy="1.570796326794896558 4.3175339846626856823e-16 -2.8792697338234302038e-14" />
<geometry>
<mesh filename="file:///Users/raghav/Documents/projects/robot_arm/onshape-to-robot-examples/low-cost-robot/dc15_a01_case_f_dummy.stl.obj"/>
</geometry>
</collision>
<visual>
<origin xyz="-1.3290960555589065306e-05 0.022438012661919970459 0.016103323324962365293" rpy="1.570796326794896558 4.3175339846626856823e-16 -2.8792697338234302038e-14" />
<geometry>
<mesh filename="file:///Users/raghav/Documents/projects/robot_arm/onshape-to-robot-examples/low-cost-robot/dc15_a01_case_b_dummy.stl.obj"/>
</geometry>
<material name="dc15_a01_case_b_dummy_material">
<color rgba="0.49803921568627451677 0.49803921568627451677 0.49803921568627451677 1.0"/>
</material>
</visual>
<collision>
<origin xyz="-1.3290960555589065306e-05 0.022438012661919970459 0.016103323324962365293" rpy="1.570796326794896558 4.3175339846626856823e-16 -2.8792697338234302038e-14" />
<geometry>
<mesh filename="file:///Users/raghav/Documents/projects/robot_arm/onshape-to-robot-examples/low-cost-robot/dc15_a01_case_b_dummy.stl.obj"/>
</geometry>
</collision>
<visual>
<origin xyz="-1.3290960555589065306e-05 0.022438012661919970459 0.016103323324962365293" rpy="1.570796326794896558 4.3175339846626856823e-16 -2.8792697338234302038e-14" />
<geometry>
<mesh filename="file:///Users/raghav/Documents/projects/robot_arm/onshape-to-robot-examples/low-cost-robot/dc15_a01_horn_idle2_dummy.stl.obj"/>
</geometry>
<material name="dc15_a01_horn_idle2_dummy_material">
<color rgba="0.98039215686274505668 0.71372549019607844922 0.0039215686274509803377 1.0"/>
</material>
</visual>
<collision>
<origin xyz="-1.3290960555589065306e-05 0.022438012661919970459 0.016103323324962365293" rpy="1.570796326794896558 4.3175339846626856823e-16 -2.8792697338234302038e-14" />
<geometry>
<mesh filename="file:///Users/raghav/Documents/projects/robot_arm/onshape-to-robot-examples/low-cost-robot/dc15_a01_horn_idle2_dummy.stl.obj"/>
</geometry>
</collision>
<inertial>
<origin xyz="-1.3727471167522840808e-07 0.025986966516014255862 0.0099485232985017969798" rpy="0 0 0"/>
<mass value="0.02014488674758841899" />
<inertia ixx="4.9962562494593585984e-06" ixy="1.6489902844129108739e-10"  ixz="1.6351694841659640569e-09" iyy="3.1984411029233958983e-06" iyz="3.2861766806547839796e-07" izz="3.0162414861342707684e-06" />
</inertial>
</link>

<link name="link_5">
<visual>
<origin xyz="-0.00073840405093506325529 -0.014596969820559024811 -0.019999999791406986027" rpy="-1.570796326794896558 -1.9877680443987982189e-16 8.7370889179757957154e-30" />
<geometry>
<mesh filename="file:///Users/raghav/Documents/projects/robot_arm/onshape-to-robot-examples/low-cost-robot/static_side.stl.obj"/>
</geometry>
<material name="static_side_material">
<color rgba="0.49803921568627451677 0.49803921568627451677 0.49803921568627451677 1.0"/>
</material>
</visual>
<collision>
<origin xyz="-0.00073840405093506325529 -0.014596969820559024811 -0.019999999791406986027" rpy="-1.570796326794896558 -1.9877680443987982189e-16 8.7370889179757957154e-30" />
<geometry>
<mesh filename="file:///Users/raghav/Documents/projects/robot_arm/onshape-to-robot-examples/low-cost-robot/static_side.stl.obj"/>
</geometry>
</collision>
<visual>
<origin xyz="0.0075615962172857695278 0.008403030179440934902 -0.012999999999999997669" rpy="-1.5707963267948983344 -1.570796326794896336 0" />
<geometry>
<mesh filename="file:///Users/raghav/Documents/projects/robot_arm/onshape-to-robot-examples/low-cost-robot/dc15_a01_horn_dummy.stl.obj"/>
</geometry>
<material name="dc15_a01_horn_dummy_material">
<color rgba="0.91764705882352937127 0.91764705882352937127 0.91764705882352937127 1.0"/>
</material>
</visual>
<collision>
<origin xyz="0.0075615962172857695278 0.008403030179440934902 -0.012999999999999997669" rpy="-1.5707963267948983344 -1.570796326794896336 0" />
<geometry>
<mesh filename="file:///Users/raghav/Documents/projects/robot_arm/onshape-to-robot-examples/low-cost-robot/dc15_a01_horn_dummy.stl.obj"/>
</geometry>
</collision>
<visual>
<origin xyz="0.0075615962172857695278 0.008403030179440934902 -0.012999999999999997669" rpy="-1.5707963267948983344 -1.570796326794896336 0" />
<geometry>
<mesh filename="file:///Users/raghav/Documents/projects/robot_arm/onshape-to-robot-examples/low-cost-robot/dc15_a01_case_m_dummy.stl.obj"/>
</geometry>
<material name="dc15_a01_case_m_dummy_material">
<color rgba="0.97254901960784312376 0.52941176470588235947 0.0039215686274509803377 1.0"/>
</material>
</visual>
<collision>
<origin xyz="0.0075615962172857695278 0.008403030179440934902 -0.012999999999999997669" rpy="-1.5707963267948983344 -1.570796326794896336 0" />
<geometry>
<mesh filename="file:///Users/raghav/Documents/projects/robot_arm/onshape-to-robot-examples/low-cost-robot/dc15_a01_case_m_dummy.stl.obj"/>
</geometry>
</collision>
<visual>
<origin xyz="0.0075615962172857695278 0.008403030179440934902 -0.012999999999999997669" rpy="-1.5707963267948983344 -1.570796326794896336 0" />
<geometry>
<mesh filename="file:///Users/raghav/Documents/projects/robot_arm/onshape-to-robot-examples/low-cost-robot/dc15_a01_case_b_dummy.stl.obj"/>
</geometry>
<material name="dc15_a01_case_b_dummy_material">
<color rgba="0.49803921568627451677 0.49803921568627451677 0.49803921568627451677 1.0"/>
</material>
</visual>
<collision>
<origin xyz="0.0075615962172857695278 0.008403030179440934902 -0.012999999999999997669" rpy="-1.5707963267948983344 -1.570796326794896336 0" />
<geometry>
<mesh filename="file:///Users/raghav/Documents/projects/robot_arm/onshape-to-robot-examples/low-cost-robot/dc15_a01_case_b_dummy.stl.obj"/>
</geometry>
</collision>
<visual>
<origin xyz="0.0075615962172857695278 0.008403030179440934902 -0.012999999999999997669" rpy="-1.5707963267948983344 -1.570796326794896336 0" />
<geometry>
<mesh filename="file:///Users/raghav/Documents/projects/robot_arm/onshape-to-robot-examples/low-cost-robot/dc15_a01_case_f_dummy.stl.obj"/>
</geometry>
<material name="dc15_a01_case_f_dummy_material">
<color rgba="0.2313725490196078538 0.38039215686274507888 0.7058823529411765163 1.0"/>
</material>
</visual>
<collision>
<origin xyz="0.0075615962172857695278 0.008403030179440934902 -0.012999999999999997669" rpy="-1.5707963267948983344 -1.570796326794896336 0" />
<geometry>
<mesh filename="file:///Users/raghav/Documents/projects/robot_arm/onshape-to-robot-examples/low-cost-robot/dc15_a01_case_f_dummy.stl.obj"/>
</geometry>
</collision>
<visual>
<origin xyz="0.0075615962172857695278 0.008403030179440934902 -0.012999999999999997669" rpy="-1.5707963267948983344 -1.570796326794896336 0" />
<geometry>
<mesh filename="file:///Users/raghav/Documents/projects/robot_arm/onshape-to-robot-examples/low-cost-robot/dc15_a01_horn_idle2_dummy.stl.obj"/>
</geometry>
<material name="dc15_a01_horn_idle2_dummy_material">
<color rgba="0.98039215686274505668 0.71372549019607844922 0.0039215686274509803377 1.0"/>
</material>
</visual>
<collision>
<origin xyz="0.0075615962172857695278 0.008403030179440934902 -0.012999999999999997669" rpy="-1.5707963267948983344 -1.570796326794896336 0" />
<geometry>
<mesh filename="file:///Users/raghav/Documents/projects/robot_arm/onshape-to-robot-examples/low-cost-robot/dc15_a01_horn_idle2_dummy.stl.obj"/>
</geometry>
</collision>
<inertial>
<origin xyz="-0.0054703320364747620719 0.00035379515409707939936 -0.019051616122921055663" rpy="0 0 0"/>
<mass value="0.030372604944475710409" />
<inertia ixx="9.1569420585346864163e-06" ixy="-8.1820000551915194547e-08"  ixz="-2.3805406784591239171e-06" iyy="1.1172203698048003071e-05" iyz="-9.9473275643207476807e-08" izz="5.7316274667953594896e-06" />
</inertial>
</link>

<link name="moving_side">
<visual>
<origin xyz="-0.0083819851589327781793 -0.00025659138241630741195 -0.0029999999999999991951" rpy="-1.1135065923926955059e-29 -1.2322091632004557242e-29 -1.0955131568305524831e-17" />
<geometry>
<mesh filename="file:///Users/raghav/Documents/projects/robot_arm/onshape-to-robot-examples/low-cost-robot/moving_side.stl.obj"/>
</geometry>
<material name="moving_side_material">
<color rgba="0.98039215686274505668 0.71372549019607844922 0.0039215686274509803377 1.0"/>
</material>
</visual>
<collision>
<origin xyz="-0.0083819851589327781793 -0.00025659138241630741195 -0.0029999999999999991951" rpy="-1.1135065923926955059e-29 -1.2322091632004557242e-29 -1.0955131568305524831e-17" />
<geometry>
<mesh filename="file:///Users/raghav/Documents/projects/robot_arm/onshape-to-robot-examples/low-cost-robot/moving_side.stl.obj"/>
</geometry>
</collision>
<inertial>
<origin xyz="-0.001343566454291784994 0.025135301999220375363 0.014439844386180466368" rpy="0 0 0"/>
<mass value="0.013481537390803315091" />
<inertia ixx="3.6022701795934831006e-06" ixy="3.2629783186034229359e-07"  ixz="-3.9974318379365274922e-09" iyy="1.5882880782810282268e-06" iyz="3.5648119287034674427e-08" izz="2.5627106954324399488e-06" />
</inertial>
</link>

<joint name="revolute_6" type="revolute">
<origin xyz="0.0075615962172857764667 -0.014096969820559412945 -0.013000000000000011546" rpy="-1.5707963267949043296 -1.5707963267948961139 0" />
<parent link="link_5" />
<child link="moving_side" />
<axis xyz="0 0 1"/>
<limit effort="1" velocity="20" lower="0" upper="1.570796326794896558"/>
<joint_properties friction="0.0"/>
</joint>

<joint name="revolute_5" type="revolute">
<origin xyz="-1.3290960555589065306e-05 0.044938012661920267998 0.016103323324962327129" rpy="1.570796326794896558 -1.4226651757087750666e-13 -3.6590717946897034832e-14" />
<parent link="link_4" />
<child link="link_5" />
<axis xyz="0 0 1"/>
<limit effort="1" velocity="20" />
<joint_properties friction="0.0"/>
</joint>

<joint name="revolute_4" type="revolute">
<origin xyz="-0.088061251076824997863 0.020691030053721970461 0.029249999999996334488" rpy="-3.1415926535897704674 1.2537591768427703134e-14 2.8797932657906102349" />
<parent link="link_3" />
<child link="link_4" />
<axis xyz="0 0 1"/>
<limit effort="1" velocity="20" lower="-3.141592653589793116" upper="0"/>
<joint_properties friction="0.0"/>
</joint>

<joint name="revolute_3" type="revolute">
<origin xyz="0.10830000000000009064 0.014800000000000014533 0.033249999999999974021" rpy="-3.141592653589793116 -1.4009660070010899428e-15 -1.6021880229056242317" />
<parent link="link_2" />
<child link="link_3" />
<axis xyz="0 0 1"/>
<limit effort="1" velocity="20" lower="-2.356194490192344837" upper="2.356194490192344837"/>
<joint_properties friction="0.0"/>
</joint>

<joint name="revolute_2" type="revolute">
<origin xyz="0.018341325102363633531 0.0015766639709812041437 -0.01615000000000188507" rpy="1.5707963267949087705 -0.010233524140060406768 -1.5707963267948970021" />
<parent link="link_1" />
<child link="link_2" />
<axis xyz="0 0 1"/>
<limit effort="1" velocity="20" lower="-2.356194490192344837" upper="2.356194490192344837"/>
<joint_properties friction="0.0"/>
</joint>

<joint name="revolute_1" type="revolute">
<origin xyz="-6.2657287344346606337e-05 0.041609087822019434622 0.039082062936782839546" rpy="-3.141592653589793116 1.0334077858395438501e-28 -2.4673782128980191759e-15" />
<parent link="link_0" />
<child link="link_1" />
<axis xyz="0 0 1"/>
<limit effort="1" velocity="20" lower="-1.0471975511965976313" upper="1.0471975511965976313"/>
<joint_properties friction="0.0"/>
</joint>




    <transmission name="revolute_1_tran">
      <type>transmission_interface/SimpleTransmission</type>
      <joint name="revolute_1">
        <hardwareInterface>hardware_interface/EffortJointInterface</hardwareInterface>
      </joint>
      <actuator name="revolute_1_actr">
        <hardwareInterface>hardware_interface/EffortJointInterface</hardwareInterface>
        <mechanicalReduction>1</mechanicalReduction>
      </actuator>
    </transmission>

    <transmission name="revolute_2_tran">
      <type>transmission_interface/SimpleTransmission</type>
      <joint name="revolute_2">
        <hardwareInterface>hardware_interface/EffortJointInterface</hardwareInterface>
      </joint>
      <actuator name="revolute_2_actr">
        <hardwareInterface>hardware_interface/EffortJointInterface</hardwareInterface>
        <mechanicalReduction>1</mechanicalReduction>
      </actuator>
    </transmission>

    <transmission name="revolute_3_tran">
      <type>transmission_interface/SimpleTransmission</type>
      <joint name="revolute_3">
        <hardwareInterface>hardware_interface/EffortJointInterface</hardwareInterface>
      </joint>
      <actuator name="revolute_3_actr">
        <hardwareInterface>hardware_interface/EffortJointInterface</hardwareInterface>
        <mechanicalReduction>1</mechanicalReduction>
      </actuator>
    </transmission>

    <transmission name="revolute_4_tran">
      <type>transmission_interface/SimpleTransmission</type>
      <joint name="revolute_4">
        <hardwareInterface>hardware_interface/EffortJointInterface</hardwareInterface>
      </joint>
      <actuator name="revolute_4_actr">
        <hardwareInterface>hardware_interface/EffortJointInterface</hardwareInterface>
        <mechanicalReduction>1</mechanicalReduction>
      </actuator>
    </transmission>

    <transmission name="revolute_5_tran">
      <type>transmission_interface/SimpleTransmission</type>
      <joint name="revolute_5">
        <hardwareInterface>hardware_interface/EffortJointInterface</hardwareInterface>
      </joint>
      <actuator name="revolute_5_actr">
        <hardwareInterface>hardware_interface/EffortJointInterface</hardwareInterface>
        <mechanicalReduction>1</mechanicalReduction>
      </actuator>
    </transmission>

    <transmission name="revolute_6_tran">
      <type>transmission_interface/SimpleTransmission</type>
      <joint name="revolute_6">
        <hardwareInterface>hardware_interface/EffortJointInterface</hardwareInterface>
      </joint>
      <actuator name="revolute_6_actr">
        <hardwareInterface>hardware_interface/EffortJointInterface</hardwareInterface>
        <mechanicalReduction>1</mechanicalReduction>
      </actuator>
    </transmission>
</robot>